<?xml version="1.0" encoding="utf-8"?>
<!-- This URDF was automatically created by SolidWorks to URDF Exporter! Originally created by Stephen Brawner (brawner@gmail.com) 
     Commit Version: 1.6.0-4-g7f85cfe  Build Version: 1.6.7995.38578
     For more information, please see http://wiki.ros.org/sw_urdf_exporter -->
<robot
  name="robot_assembly.SLDASM">
  <link
    name="base_link">
    <inertial>
      <origin
        xyz="3.2814E-18 0.026189 0.001556"
        rpy="0 0 0" />
      <mass
        value="0.26433" />
      <inertia
        ixx="0.00015157"
        ixy="2.1101E-20"
        ixz="2.5808E-20"
        iyy="0.00020961"
        iyz="-1.0564E-06"
        izz="0.0001781" />
    </inertial>
    <visual>
      <origin
        xyz="0 0 0"
        rpy="0 0 0" />
      <geometry>
        <mesh
          filename="package://robot_assembly.SLDASM/meshes/base_link.STL" />
      </geometry>
      <material
        name="">
        <color
          rgba="1 1 1 1" />
      </material>
    </visual>
    <collision>
      <origin
        xyz="0 0 0"
        rpy="0 0 0" />
      <geometry>
        <mesh
          filename="package://robot_assembly.SLDASM/meshes/base_link.STL" />
      </geometry>
    </collision>
  </link>
  <link
    name="RightWheelLink">
    <inertial>
      <origin
        xyz="-6.9389E-18 -4.8572E-17 -0.015957"
        rpy="0 0 0" />
      <mass
        value="0.086761" />
      <inertia
        ixx="2.8632E-05"
        ixy="1.6941E-21"
        ixz="-3.3692E-21"
        iyy="2.8632E-05"
        iyz="-1.2838E-20"
        izz="4.7824E-05" />
    </inertial>
    <visual>
      <origin
        xyz="0 0 0"
        rpy="0 0 0" />
      <geometry>
        <mesh
          filename="package://robot_assembly.SLDASM/meshes/RightWheelLink.STL" />
      </geometry>
      <material
        name="">
        <color
          rgba="0.79216 0.81961 0.93333 1" />
      </material>
    </visual>
    <collision>
      <origin
        xyz="0 0 0"
        rpy="0 0 0" />
      <geometry>
        <mesh
          filename="package://robot_assembly.SLDASM/meshes/RightWheelLink.STL" />
      </geometry>
    </collision>
  </link>
  <joint
    name="RightWheelJoint"
    type="continuous">
    <origin
      xyz="-0.063 -0.0185 0.032"
      rpy="-1.5708 -1.257 -1.5708" />
    <parent
      link="base_link" />
    <child
      link="RightWheelLink" />
    <axis
      xyz="0 0 1" />
  </joint>
  <link
    name="LeftWheelLink">
    <inertial>
      <origin
        xyz="0 0 0"
        rpy="0 0 0" />
      <mass
        value="0" />
      <inertia
        ixx="0"
        ixy="0"
        ixz="0"
        iyy="0"
        iyz="0"
        izz="0" />
    </inertial>
    <visual>
      <origin
        xyz="0 0 0"
        rpy="0 0 0" />
      <geometry>
        <mesh
          filename="package://robot_assembly.SLDASM/meshes/LeftWheelLink.STL" />
      </geometry>
      <material
        name="">
        <color
          rgba="1 1 1 1" />
      </material>
    </visual>
    <collision>
      <origin
        xyz="0 0 0"
        rpy="0 0 0" />
      <geometry>
        <mesh
          filename="package://robot_assembly.SLDASM/meshes/LeftWheelLink.STL" />
      </geometry>
    </collision>
  </link>
  <joint
    name="LeftWheelJoint"
    type="continuous">
    <origin
      xyz="0.063 -0.0185 0.032"
      rpy="-1.5708 -1.1445 1.5708" />
    <parent
      link="base_link" />
    <child
      link="LeftWheelLink" />
    <axis
      xyz="0 0 1" />
  </joint>
</robot>